Workbook
Name UPDATE: 'Data Sheet'!$E$1

Sheet Sheet2
K4: ASSUMPTIONS
C5: SOTP based on geography
K6: Sales on 2025 | L6: ='Profit & Loss'!L4 -> 24750.69
B7: % as of 2025 | C7: Geography | D7: 2025 | E7: 2026 | F7: 2027 | G7: 2028 | H7: 2029 | I7: 2030 | K7: Growth Rates | M7: Concall Guidance
B8: 0.412 | C8: USA and UK | D8: =B8*L$6 -> 10197.284 | E8: =D8*(1+0.14) -> 11624.904 | F8: =E8*(1+0.14) -> 13252.391 | G8: =F8*(1+0.14) -> 15107.725 | H8: =G8*(1+0.1) -> 16618.498 | I8: =H8*(1+0.1) -> 18280.348 | K8: 14% (26-28) High growth | L8: 10%(29-30) Lower growth | M8: Higher growth in the initial year due to new products followed by sustainabiliy
B9: 0.351 | C9: INDIA | D9: =B9*L$6 -> 8687.4922 | E9: =(1+0.095)*D9 -> 9512.8039 | F9: =(1+0.095)*E9 -> 10416.52 | G9: =(1+0.095)*F9 -> 11406.09 | H9: =(1+0.095)*G9 -> 12489.668 | I9: =(1+0.095)*H9 -> 13676.187 | K9: 0.095 | M9: 1*2 Times The IPM
B10: =100%-B8-B9 -> 0.237 | C10: Other Markets | D10: =B10*L$6 -> 5865.9135 | E10: =1.11*D10 -> 6511.164 | F10: =1.11*E10 -> 7227.3921 | G10: =1.11*F10 -> 8022.4052 | H10: =1.11*G10 -> 8904.8698 | I10: =1.11*H10 -> 9884.4054 | K10: 0.11 | M10: Sustained groth in brazil and SA for the next years
C11: Net Sales | D11: =D8+D9+D10 -> 24750.69 | E11: =E8+E9+E10 -> 27648.872 | F11: =F8+F9+F10 -> 30896.303 | G11: =G8+G9+G10 -> 34536.22 | H11: =H8+H9+H10 -> 38013.036 | I11: =I8+I9+I10 -> 41840.94

Sheet Sheet1
J5: Assumptions
J6: EBIT
J7: Tax Rate % | K7: ='Data Sheet'!G37 -> 0.25503851
J8: D&A | K8: 5% of sales
J9: CapEx
C10: 2025 | D10: 2026 | E10: 2027 | F10: 2028 | G10: 2029 | H10: 2030 | J10: Non-cash Working Capital
B11: Sales | C11: 24750.69 | D11: 27648.872 | E11: 30896.303 | F11: 34536.22 | G11: 38013.036 | H11: 41840.94 | J11: Average Assest Turnover | K11: ='Data Sheet'!G102 -> 0.76524631
B12: D&A | C12: =C11*0.05 -> 1237.5345 | D12: =D11*0.05 -> 1382.4436 | E12: =E11*0.05 -> 1544.8152 | F12: =F11*0.05 -> 1726.811 | G12: =G11*0.05 -> 1900.6518 | H12: =H11*0.05 -> 2092.047 | J12: Average Interest Growth Rate | K12: 8.1
B14: EBITDA Margins (Conservative) | C14: 0.23 | D14: 0.23 | E14: 0.23 | F14: 0.23 | G14: 0.23 | H14: 0.23 | J14: Expected EBITDA margins mentioned in con calls
B15: EBITDA Margins (Base) | C15: 0.24 | D15: 0.24 | E15: 0.24 | F15: 0.24 | G15: 0.24 | H15: 0.24
B16: EBITDA Margins (Growth) | C16: 0.25 | D16: 0.25 | E16: 0.25 | F16: 0.25 | G16: 0.25 | H16: 0.25
B18: EBITDA | D18: =D14*D11 -> 6359.2406 | E18: =E14*E11 -> 7106.1497 | F18: =F14*F11 -> 7943.3307 | G18: =G14*G11 -> 8742.9983 | H18: =H14*H11 -> 9623.4162
B19: Working Capital Changes | D19: ='Data Sheet'!G39*Sheet1!D11 -> 381.77131 | E19: ='Data Sheet'!G39*Sheet1!E11 -> 426.61133 | F19: ='Data Sheet'!G39*Sheet1!F11 -> 476.87073 | G19: ='Data Sheet'!G39*Sheet1!G11 -> 524.87806 | H19: ='Data Sheet'!G39*Sheet1!H11 -> 577.73316
B20: Interest | C20: ='Data Sheet'!K29 -> 294.87 | D20: =C20*(1+K12/100) -> 318.75447 | E20: =D20*(1+K12/100) -> 344.57358 | F20: =E20*(1+K12/100) -> 372.48404 | G20: =F20*(1+K12/100) -> 402.65525 | H20: =G20*(1+K12/100) -> 435.27032
B21: Profit Before Tax | D21: =D18-D20-D12 -> 4658.0425 | E21: =E18-E20-E12 -> 5216.761 | F21: =F18-F20-F12 -> 5844.0356 | G21: =G18-G20-G12 -> 6439.6912 | H21: =H18-H20-H12 -> 7096.0989
B22: Tax | D22: =K7*D21 -> 1187.9802 | E22: =K7*E21 -> 1330.475 | F22: =K7*F21 -> 1490.4541 | G22: =K7*G21 -> 1642.3693 | H22: =K7*H21 -> 1809.7785
B24: Free Cash Flow | D24: =D18-D8-D19-D22 -> 4789.489 | E24: =E18-E8-E19-E22 -> 5349.0634 | F24: =F18-F8-F19-F22 -> 5976.0058 | G24: =G18-G8-G19-G22 -> 6575.7509 | H24: =H18-H8-H19-H22 -> 7235.9045

Sheet WACC
B2: WACC Calculation
B4: Equity value | C4: 17294.3
B5: Debt value | C5: ='Data Sheet'!K64 -> 5447.77
B6: Cost of Debt | C6: 0.081
B7: Tax rate | C7: 0.27
B8: Risk Free Rate | C8: 0.066
B9: Beta | C9: 0.33
B10: Market Return | C10: 0.13
B11: Cost of Equity | C11: =C8+C9*(C10-C8) -> 0.08712
B13: E / D +E | C13: =((C4/(C5+C4)))*C11 -> 0.06625076
B14: D / D+E | C14: =(C5/(C5+C4))*C6*(1-C7) -> 0.01416435
B15: WACC | C15: =C13+C14 -> 0.08041511

Sheet DCF
C2: WACC | D2: =WACC!C15 -> 0.08041511
C4: Unlevered Free Cash Flow
C5: Fiscal year | E5: 2025-26 | F5: 2026-27 | G5: 2027-28 | H5: 2028-29 | I5: 2029-30
C6: Unlevered Free Cash Flow | E6: =Sheet1!D24 -> 4789.489 | F6: =Sheet1!E24 -> 5349.0634 | G6: =Sheet1!F24 -> 5976.0058 | H6: =Sheet1!G24 -> 6575.7509 | I6: =Sheet1!H24 -> 7235.9045
C7: Projection Year | E7: 1 | F7: 2 | G7: 3 | H7: 4 | I7: 5
C8: PV of FCF | E8: =E6/((1+DCF!D2)^DCF!E7) -> 4433.0082 | F8: =F6/((1+DCF!D2)^DCF!F7) -> 4582.4364 | G8: =G6/((1+DCF!D2)^DCF!G7) -> 4738.4801 | H8: =H6/((1+DCF!D2)^DCF!H7) -> 4825.9493 | I8: =I6/((1+DCF!D2)^DCF!I7) -> 4915.1817
C11: Implied Share Price Calculation
C12: Sum of PV of Free Cash Flow | E12: =SUM(E8:I8) -> 23495.056
C13: Growth | E13: 0.035
C14: WACC | E14: =D2 -> 0.08041511
C15: Terminal Value | E15: =I6*(1+E13)/(E14-E13) -> 164904.61
C16: PV of Terminal Value | E16: =E15/((1+E14)^I7) -> 112015.87
C17: Enterprise Value | E17: =E16+E12 -> 135510.93
C18: (+) Cash | E18: ='Data Sheet'!K74 -> 3142.33
C19: (-) Debt | E19: ='Data Sheet'!K64 -> 5447.77
C20: Equity Value | E20: =E17+E18-E19 -> 133205.49
C21: Diluted Shares Outstanding | E21: 45.6565
C22: Implied Share Price | E22: =E20/E21 -> 2917.558

Sheet Data Sheet
A1: COMPANY NAME | B1: LUPIN LTD | E1: =IF(B2<>B3, "A NEW VERSION OF THE WORKSHEET IS AVAILABLE", "")
A2: LATEST VERSION | B2: 2.1 | E2: PLEASE DO NOT MAKE ANY CHANGES TO THIS SHEET
A3: CURRENT VERSION | B3: 2.1
A5: META
A6: Number of shares | B6: =IF(B9>0, B9/B8, 0) -> 45.679886
A7: Face Value | B7: 2
A8: Current Price | B8: 2099
A9: Market Capitalization | B9: 95882.08
A15: PROFIT & LOSS
A16: Report Date | B16: 42460 | C16: 42825 | D16: 43190 | E16: 43555 | F16: 43921 | G16: 44286 | H16: 44651 | I16: 45016 | J16: 45382 | K16: 45747
A17: Sales | B17: 14255.54 | C17: 17367.38 | D17: 15796.55 | E17: 14664.56 | F17: 15374.76 | G17: 15162.96 | H17: 16405.48 | I17: 16641.66 | J17: 20010.82 | K17: 22707.9
A18: Raw Material Cost | B18: 4778.49 | C18: 5339.31 | D18: 5111.62 | E18: 5150.54 | F18: 5422.05 | G18: 5847.1 | H18: 6679.56 | I18: 6626.03 | J18: 7100.91 | K18: 7100.03
A19: Change in Inventory | B19: 445.92 | C19: 337.88 | D19: -162.78 | E19: 204.45 | F19: -8.55 | G19: 484.86 | H19: 198.32 | I19: -153.73 | J19: 457.44 | K19: 257.78
A20: %change wrt sales | B20: =B19/B17 -> 0.031280471 | C20: =C19/C17 -> 0.019454863 | D20: =D19/D17 -> -0.010304782 | E20: =E19/E17 -> 0.013941775 | F20: =F19/F17 -> -0.00055610624 | G20: =G19/G17 -> 0.031976606 | H20: =H19/H17 -> 0.012088644 | I20: =I19/I17 -> -0.0092376602 | ... K20: =K19/K17 -> 0.011351996
A21: Power and Fuel | B21: 381.27 | C21: 377.86 | D21: 433.88 | E21: 442.28 | F21: 443.17 | G21: 414.48 | H21: 443.96 | I21: 479.68 | J21: 493.07 | K21: 479.09
A22: Other Mfr. Exp | B22: 1102.07 | C22: 1802.78 | D22: 1539.28 | E22: 1222.15 | F22: 1384.33 | G22: 1437.71 | H22: 1487.59 | I22: 1420.26 | J22: 1739.58 | K22: 1982.33
A23: Employee Cost | B23: 2141.79 | C23: 2849.64 | D23: 2864.85 | E23: 2770.31 | F23: 2987.05 | G23: 2826.08 | H23: 2989.53 | I23: 3087.32 | J23: 3494.57 | K23: 3964.2
A24: Selling and admin | B24: 2369.09 | C24: 2377.05 | D24: 2386.73 | E24: 2512.93 | F24: 2540.95 | G24: 2230.45 | H24: 2490.33 | I24: 2755.37 | J24: 3350.86 | K24: 3676.16
A25: Other Expenses | B25: 237.68 | C25: 456.67 | D25: 149.9 | E25: 210.08 | F25: 233.86 | G25: 325.12 | H25: 2294.01 | I25: 398.7 | J25: 489.26 | K25: 486.35
A26: Other Income | B26: 184.37 | C26: 105.95 | D26: -1310.48 | E26: 91.24 | F26: -134.27 | G26: 137.62 | H26: 210.45 | I26: 150.91 | J26: 130.68 | K26: 201.61
A28: Depreciation | B28: 487.13 | C28: 912.23 | D28: 1085.87 | E28: 846.05 | F28: 970.22 | G28: 887.41 | H28: 1658.71 | I28: 880.69 | J28: 1196.81 | K28: 1169.26
A29: Interest | B29: 59.47 | C29: 152.53 | D29: 204.35 | E29: 302.49 | F29: 362.98 | G29: 140.64 | H29: 142.77 | I29: 274.3 | J29: 311.61 | K29: 294.87
A30: Interest Growth | C30: =(C29-B29)/B29 -> 1.5648226 | D30: =(D29-C29)/C29 -> 0.33973645 | E30: =(E29-D29)/D29 -> 0.48025447 | F30: =(F29-E29)/E29 -> 0.19997355 | G30: =(G29-F29)/F29 -> -0.61254064 | H30: =(H29-G29)/G29 -> 0.015145051 | I30: =(I29-H29)/H29 -> 0.92127198 | J30: =(J29-I29)/I29 -> 0.13601896 | K30: =(K29-J29)/J29 -> -0.053720997
A31: Profit before tax | B31: 3328.84 | C31: 3543.14 | D31: 546.81 | E31: 1503.42 | F31: 887.33 | G31: 1676.45 | H31: -1372.21 | I31: 716.49 | J31: 2422.27 | K31: 4015
A32: Tax | B32: 1059.34 | C32: 978.51 | D32: 288.46 | E32: 887.94 | F32: 1157.11 | G32: 448.52 | H32: 137.15 | I32: 268.8 | J32: 486.7 | K32: 708.74
A33: Tax percent | B33: =B32/B31 -> 0.31823098 | C33: =C32/C31 -> 0.27617029 | D33: =D32/D31 -> 0.52753242 | E33: =E32/E31 -> 0.5906134 | F33: =F32/F31 -> 1.3040357 | G33: =G32/G31 -> 0.26754153 | H33: =H32/H31 -> -0.099948259 | I33: =I32/I31 -> 0.37516225 | ... K33: =K32/K31 -> 0.17652304
A34: Net profit | B34: 2260.74 | C34: 2557.46 | D34: 251.26 | E34: 606.55 | F34: -269.39 | G34: 1216.53 | H34: -1528.04 | I34: 430.08 | J34: 1914.48 | K34: 3281.62
A35: Dividend Amount | B35: 337.95 | C35: 338.7 | D35: 226.05 | E35: 226.25 | F35: 271.8 | G35: 294.9 | H35: 181.8 | I35: 182 | J35: 364.56 | K35: 547.92
F37: Avg Tax rate | G37: =AVERAGE(G33,I33,J33,K33) -> 0.25503851
F38: Avg Interest Growth | G38: =AVERAGE(G30:K30) -> 0.08123487
F39: Avg Change in Working Capital wrt Sale | G39: =AVERAGE(G20:K20) -> 0.013807844
F40: Cost of Debt | G40: =K29/K64 -> 0.054126734
A44: Quarters
A45: Report Date | B45: 45107 | C45: 45199 | D45: 45291 | E45: 45382 | F45: 45473 | G45: 45565 | H45: 45657 | I45: 45747 | J45: 45838 | K45: 45930
A46: Sales | B46: 4814.06 | C46: 5038.56 | D46: 5197.41 | E46: 4960.79 | F46: 5600.33 | G46: 5672.73 | H46: 5767.71 | I46: 5667.13 | J46: 6268.34 | K46: 7047.51
A47: Expenses | B47: 3957.77 | C47: 4120.8 | D47: 4159.47 | E47: 3963.94 | F47: 4359.36 | G47: 4332.37 | H47: 4411.81 | I47: 4345.96 | J47: 4541.1 | K47: 4706.18
A48: Other Income | B48: 22.83 | C48: 40.4 | D48: 29.37 | E48: 29.25 | F48: 67.78 | G48: 42.29 | H48: 53.71 | I48: 56.95 | J48: 79.04 | K48: 90
A49: Depreciation | B49: 234.66 | C49: 247.85 | D49: 257.2 | E49: 457.1 | F49: 247.71 | G49: 256.92 | H49: 271.45 | I49: 393.18 | J49: 298.98 | K49: 316.77
A50: D&A as a % of sales | B50: =B49/B46 -> 0.048744719 | C50: =C49/C46 -> 0.049190642 | D50: =D49/D46 -> 0.049486186 | E50: =E49/E46 -> 0.092142582 | F50: =F49/F46 -> 0.044231322 | G50: =G49/G46 -> 0.045290363 | H50: =H49/H46 -> 0.047063739 | I50: =I49/I46 -> 0.069379033 | ... K50: =K49/K46 -> 0.04494779
A51: Interest | B51: 85.67 | C51: 80.64 | D51: 74.01 | E51: 71.29 | F51: 68.01 | G51: 70.87 | H51: 66.89 | I51: 89.1 | J51: 91.76 | K51: 107.59
...

Sheet Profit & Loss
A1: ='Data Sheet'!B1 -> LUPIN LTD | H1: =UPDATE | M1: SCREENER.IN
A3: Narration | B3: ='Data Sheet'!B16 -> 42460 | C3: ='Data Sheet'!C16 -> 42825 | D3: ='Data Sheet'!D16 -> 43190 | E3: ='Data Sheet'!E16 -> 43555 | F3: ='Data Sheet'!F16 -> 43921 | G3: ='Data Sheet'!G16 -> 44286 | H3: ='Data Sheet'!H16 -> 44651 | I3: ='Data Sheet'!I16 -> 45016 | ... K3: ='Data Sheet'!K16 -> 45747 | L3: Trailing | M3: Best Case | N3: Worst Case
A4: Sales | B4: ='Data Sheet'!B17 -> 14255.54 | C4: ='Data Sheet'!C17 -> 17367.38 | D4: ='Data Sheet'!D17 -> 15796.55 | E4: ='Data Sheet'!E17 -> 14664.56 | F4: ='Data Sheet'!F17 -> 15374.76 | G4: ='Data Sheet'!G17 -> 15162.96 | H4: ='Data Sheet'!H17 -> 16405.48 | I4: ='Data Sheet'!I17 -> 16641.66 | ... K4: ='Data Sheet'!K17 -> 22707.9 | L4: =SUM(Quarters!H4:K4) -> 24750.69 | M4: =$K4+M23*K4 -> 25768.495 | N4: =$K4+N23*L4 -> 24021.94
A5: Expenses | B5: =SUM('Data Sheet'!B18,'Data Sheet'!B21:B25, -1*'Data Sheet'!B19) -> 10564.47 | C5: =SUM('Data Sheet'!C18,'Data Sheet'!C21:C25, -1*'Data Sheet'!C19) -> 12865.43 | D5: =SUM('Data Sheet'!D18,'Data Sheet'!D21:D25, -1*'Data Sheet'!D19) -> 12649.04 | E5: =SUM('Data Sheet'!E18,'Data Sheet'!E21:E25, -1*'Data Sheet'!E19) -> 12103.84 | F5: =SUM('Data Sheet'!F18,'Data Sheet'!F21:F25, -1*'Data Sheet'!F19) -> 13019.96 | G5: =SUM('Data Sheet'!G18,'Data Sheet'!G21:G25, -1*'Data Sheet'!G19) -> 12596.08 | H5: =SUM('Data Sheet'!H18,'Data Sheet'!H21:H25, -1*'Data Sheet'!H19) -> 16186.66 | I5: =SUM('Data Sheet'!I18,'Data Sheet'!I21:I25, -1*'Data Sheet'!I19) -> 14921.09 | ... K5: =SUM('Data Sheet'!K18,'Data Sheet'!K21:K25, -1*'Data Sheet'!K19) -> 17430.38 | L5: =SUM(Quarters!H5:K5) -> 18005.05 | M5: =M4-M6 -> 18745.459 | N5: =N4-N6 -> 20433.317
A6: Operating Profit | B6: =B4-B5 -> 3691.07 | C6: =C4-C5 -> 4501.95 | D6: =D4-D5 -> 3147.51 | E6: =E4-E5 -> 2560.72 | F6: =F4-F5 -> 2354.8 | G6: =G4-G5 -> 2566.88 | H6: =H4-H5 -> 218.82 | I6: =I4-I5 -> 1720.57 | ... K6: =K4-K5 -> 5277.52 | L6: =SUM(Quarters!H6:K6) -> 6745.64 | M6: =M4*M24 -> 7023.0362 | N6: =N4*N24 -> 3588.6227
A7: Other Income | B7: ='Data Sheet'!B26 -> 184.37 | C7: ='Data Sheet'!C26 -> 105.95 | D7: ='Data Sheet'!D26 -> -1310.48 | E7: ='Data Sheet'!E26 -> 91.24 | F7: ='Data Sheet'!F26 -> -134.27 | G7: ='Data Sheet'!G26 -> 137.62 | H7: ='Data Sheet'!H26 -> 210.45 | I7: ='Data Sheet'!I26 -> 150.91 | ... K7: ='Data Sheet'!K26 -> 201.61 | L7: =SUM(Quarters!H7:K7) -> 279.7 | M7: 0 | N7: 0
A8: Depreciation | B8: ='Data Sheet'!B28 -> 487.13 | C8: ='Data Sheet'!C28 -> 912.23 | D8: ='Data Sheet'!D28 -> 1085.87 | E8: ='Data Sheet'!E28 -> 846.05 | F8: ='Data Sheet'!F28 -> 970.22 | G8: ='Data Sheet'!G28 -> 887.41 | H8: ='Data Sheet'!H28 -> 1658.71 | I8: ='Data Sheet'!I28 -> 880.69 | ... K8: ='Data Sheet'!K28 -> 1169.26 | L8: =SUM(Quarters!H8:K8) -> 1280.38 | M8: =+$L8 -> 1280.38 | N8: =+$L8 -> 1280.38
A9: Interest | B9: ='Data Sheet'!B29 -> 59.47 | C9: ='Data Sheet'!C29 -> 152.53 | D9: ='Data Sheet'!D29 -> 204.35 | E9: ='Data Sheet'!E29 -> 302.49 | F9: ='Data Sheet'!F29 -> 362.98 | G9: ='Data Sheet'!G29 -> 140.64 | H9: ='Data Sheet'!H29 -> 142.77 | I9: ='Data Sheet'!I29 -> 274.3 | ... K9: ='Data Sheet'!K29 -> 294.87 | L9: =SUM(Quarters!H9:K9) -> 355.34 | M9: =+$L9 -> 355.34 | N9: =+$L9 -> 355.34
A10: Profit before tax | B10: ='Data Sheet'!B31 -> 3328.84 | C10: ='Data Sheet'!C31 -> 3543.14 | D10: ='Data Sheet'!D31 -> 546.81 | E10: ='Data Sheet'!E31 -> 1503.42 | F10: ='Data Sheet'!F31 -> 887.33 | G10: ='Data Sheet'!G31 -> 1676.45 | H10: ='Data Sheet'!H31 -> -1372.21 | I10: ='Data Sheet'!I31 -> 716.49 | ... K10: ='Data Sheet'!K31 -> 4015 | L10: =SUM(Quarters!H10:K10) -> 5389.62 | M10: =M6+M7-SUM(M8:M9) -> 5387.3162 | N10: =N6+N7-SUM(N8:N9) -> 1952.9027
A11: Tax | B11: ='Data Sheet'!B32 -> 1059.34 | C11: ='Data Sheet'!C32 -> 978.51 | D11: ='Data Sheet'!D32 -> 288.46 | E11: ='Data Sheet'!E32 -> 887.94 | F11: ='Data Sheet'!F32 -> 1157.11 | G11: ='Data Sheet'!G32 -> 448.52 | H11: ='Data Sheet'!H32 -> 137.15 | I11: ='Data Sheet'!I32 -> 268.8 | ... K11: ='Data Sheet'!K32 -> 708.74 | L11: =SUM(Quarters!H11:K11) -> 1042.09 | M11: =IF($L10>0,$L11/$L10,0) -> 0.19335129 | N11: =IF($L10>0,$L11/$L10,0) -> 0.19335129
A12: Net profit | B12: ='Data Sheet'!B34 -> 2260.74 | C12: ='Data Sheet'!C34 -> 2557.46 | D12: ='Data Sheet'!D34 -> 251.26 | E12: ='Data Sheet'!E34 -> 606.55 | F12: ='Data Sheet'!F34 -> -269.39 | G12: ='Data Sheet'!G34 -> 1216.53 | H12: ='Data Sheet'!H34 -> -1528.04 | I12: ='Data Sheet'!I34 -> 430.08 | ... K12: ='Data Sheet'!K34 -> 3281.62 | L12: =SUM(Quarters!H12:K12) -> 4324.63 | M12: =M10-M11*M10 -> 4345.6717 | N12: =N10-N11*N10 -> 1575.3065
A13: EPS | B13: =IF('Data Sheet'!B98>0,B12/'Data Sheet'!B98,0) -> 50.171771 | C13: =IF('Data Sheet'!C98>0,C12/'Data Sheet'!C98,0) -> 56.631089 | D13: =IF('Data Sheet'!D98>0,D12/'Data Sheet'!D98,0) -> 5.55762 | E13: =IF('Data Sheet'!E98>0,E12/'Data Sheet'!E98,0) -> 13.40442 | F13: =IF('Data Sheet'!F98>0,F12/'Data Sheet'!F98,0) -> -5.9467991 | G13: =IF('Data Sheet'!G98>0,G12/'Data Sheet'!G98,0) -> 26.813533 | H13: =IF('Data Sheet'!H98>0,H12/'Data Sheet'!H98,0) -> -33.620242 | I13: =IF('Data Sheet'!I98>0,I12/'Data Sheet'!I98,0) -> 9.4523077 | ... K13: =IF('Data Sheet'!K98>0,K12/'Data Sheet'!K98,0) -> 71.870784 | L13: =IF('Data Sheet'!$B6>0,'Profit & Loss'!L12/'Data Sheet'!$B6,0) -> 94.672522 | M13: =IF('Data Sheet'!$B6>0,'Profit & Loss'!M12/'Data Sheet'!$B6,0) -> 95.133156 | N13: =IF('Data Sheet'!$B6>0,'Profit & Loss'!N12/'Data Sheet'!$B6,0) -> 34.485779
A14: Price to earning | B14: =IF(B15>0,B15/B13,"") -> 29.483711 | C14: =IF(C15>0,C15/C13,"") -> 25.519551 | D14: =IF(D15>0,D15/D13,"") -> 132.4038 | E14: =IF(E15>0,E15/E13,"") -> 55.175831 | F14: =IF(F15>0,F15/F13,"") -> -99.154182 | G14: =IF(G15>0,G15/G13,"") -> 38.057275 | H14: =IF(H15>0,H15/H13,"") -> -22.220245 | I14: =IF(I15>0,I15/I13,"") -> 68.597005 | ... K14: =IF(K15>0,K15/K13,"") -> 28.216612 | L14: =IF(L13>0,L15/L13,0) -> 22.171164 | M14: =M25 -> 39.36729 | N14: =N25 -> 22.171164
A15: Price | B15: ='Data Sheet'!B95 -> 1479.25 | C15: ='Data Sheet'!C95 -> 1445.2 | D15: ='Data Sheet'!D95 -> 735.85 | E15: ='Data Sheet'!E95 -> 739.6 | F15: ='Data Sheet'!F95 -> 589.65 | G15: ='Data Sheet'!G95 -> 1020.45 | H15: ='Data Sheet'!H95 -> 747.05 | I15: ='Data Sheet'!I95 -> 648.4 | ... K15: ='Data Sheet'!K95 -> 2027.95 | L15: ='Data Sheet'!B8 -> 2099 | M15: =M13*M14 -> 3745.1346 | N15: =N13*N14 -> 764.58986
A17: RATIOS:
A18: Dividend Payout | B18: =IF('Data Sheet'!B34>0, 'Data Sheet'!B35/'Data Sheet'!B34, 0) -> 0.14948645 | C18: =IF('Data Sheet'!C34>0, 'Data Sheet'!C35/'Data Sheet'!C34, 0) -> 0.13243609 | D18: =IF('Data Sheet'!D34>0, 'Data Sheet'!D35/'Data Sheet'!D34, 0) -> 0.89966568 | E18: =IF('Data Sheet'!E34>0, 'Data Sheet'!E35/'Data Sheet'!E34, 0) -> 0.37301129 | F18: =IF('Data Sheet'!F34>0, 'Data Sheet'!F35/'Data Sheet'!F34, 0) -> 0 | G18: =IF('Data Sheet'!G34>0, 'Data Sheet'!G35/'Data Sheet'!G34, 0) -> 0.24241079 | H18: =IF('Data Sheet'!H34>0, 'Data Sheet'!H35/'Data Sheet'!H34, 0) -> 0 | I18: =IF('Data Sheet'!I34>0, 'Data Sheet'!I35/'Data Sheet'!I34, 0) -> 0.42317708 | ... K18: =IF('Data Sheet'!K34>0, 'Data Sheet'!K35/'Data Sheet'!K34, 0) -> 0.16696632
A19: OPM | B19: =IF(B6>0,B6/B4,0) -> 0.25892179 | C19: =IF(C6>0,C6/C4,0) -> 0.25921872 | D19: =IF(D6>0,D6/D4,0) -> 0.199253 | E19: =IF(E6>0,E6/E4,0) -> 0.17461963 | F19: =IF(F6>0,F6/F4,0) -> 0.15316011 | G19: =IF(G6>0,G6/G4,0) -> 0.16928621 | H19: =IF(H6>0,H6/H4,0) -> 0.013338226 | I19: =IF(I6>0,I6/I4,0) -> 0.10338933 | ... L19: =IF(L6>0,L6/L4,0) -> 0.27254351
G22: TRENDS: | H22: 10 YEARS | I22: 7 YEARS | J22: 5 YEARS | K22: 3 YEARS | L22: RECENT | M22: BEST | N22: WORST
G23: Sales Growth | H23: =IF(B4=0,"",POWER($K4/B4,1/9)-1) -> 0.053091051 | I23: =IF(D4=0,"",POWER($K4/D4,1/7)-1) -> 0.053213433 | J23: =IF(F4=0,"",POWER($K4/F4,1/5)-1) -> 0.081119562 | K23: =IF(H4=0,"",POWER($K4/H4, 1/3)-1) -> 0.11445536 | L23: =IF(ISERROR(MAX(IF(J4=0,"",(K4-J4)/J4),IF(K4=0,"",(L4-K4)/K4))),"",MAX(IF(J4=0,"",(K4-J4)/J4),IF(K4=0,"",(L4-K4)/K4))) -> 0.13478108 | M23: =MAX(K23:L23) -> 0.13478108 | N23: =MIN(H23:L23) -> 0.053091051
G24: OPM | H24: =IF(SUM(B4:$K$4)=0,"",SUMPRODUCT(B19:$K$19,B4:$K$4)/SUM(B4:$K$4)) -> 0.1772093 | I24: =IF(SUM(E4:$K$4)=0,"",SUMPRODUCT(E19:$K$19,E4:$K$4)/SUM(E4:$K$4)) -> 0.15292721 | J24: =IF(SUM(G4:$K$4)=0,"",SUMPRODUCT(G19:$K$19,G4:$K$4)/SUM(G4:$K$4)) -> 0.14938938 | K24: =IF(SUM(I4:$K$4)=0, "", SUMPRODUCT(I19:$K$19,I4:$K$4)/SUM(I4:$K$4)) -> 0.18190753 | L24: =L19 -> 0.27254351 | M24: =MAX(K24:L24) -> 0.27254351 | N24: =MIN(H24:L24) -> 0.14938938
G25: Price to Earning | H25: =IF(ISERROR(AVERAGEIF(B14:$L14,">0")),"",AVERAGEIF(B14:$L14,">0")) -> 48.678814 | I25: =IF(ISERROR(AVERAGEIF(E14:$L14,">0")),"",AVERAGEIF(E14:$L14,">0")) -> 41.783711 | J25: =IF(ISERROR(AVERAGEIF(G14:$L14,">0")),"",AVERAGEIF(G14:$L14,">0")) -> 39.105287 | K25: =IF(ISERROR(AVERAGEIF(I14:$L14,">0")),"",AVERAGEIF(I14:$L14,">0")) -> 39.36729 | L25: =L14 -> 22.171164 | M25: =MAX(K25:L25) -> 39.36729 | N25: =MIN(H25:L25) -> 22.171164

Sheet Quarters
A1: ='Profit & Loss'!A1 -> LUPIN LTD | E1: =UPDATE | J1: SCREENER.IN
A3: Narration | B3: ='Data Sheet'!B45 -> 45107 | C3: ='Data Sheet'!C45 -> 45199 | D3: ='Data Sheet'!D45 -> 45291 | E3: ='Data Sheet'!E45 -> 45382 | F3: ='Data Sheet'!F45 -> 45473 | G3: ='Data Sheet'!G45 -> 45565 | H3: ='Data Sheet'!H45 -> 45657 | I3: ='Data Sheet'!I45 -> 45747 | ... K3: ='Data Sheet'!K45 -> 45930
A4: Sales | B4: ='Data Sheet'!B46 -> 4814.06 | C4: ='Data Sheet'!C46 -> 5038.56 | D4: ='Data Sheet'!D46 -> 5197.41 | E4: ='Data Sheet'!E46 -> 4960.79 | F4: ='Data Sheet'!F46 -> 5600.33 | G4: ='Data Sheet'!G46 -> 5672.73 | H4: ='Data Sheet'!H46 -> 5767.71 | I4: ='Data Sheet'!I46 -> 5667.13 | ... K4: ='Data Sheet'!K46 -> 7047.51
A5: Expenses | B5: ='Data Sheet'!B47 -> 3957.77 | C5: ='Data Sheet'!C47 -> 4120.8 | D5: ='Data Sheet'!D47 -> 4159.47 | E5: ='Data Sheet'!E47 -> 3963.94 | F5: ='Data Sheet'!F47 -> 4359.36 | G5: ='Data Sheet'!G47 -> 4332.37 | H5: ='Data Sheet'!H47 -> 4411.81 | I5: ='Data Sheet'!I47 -> 4345.96 | ... K5: ='Data Sheet'!K47 -> 4706.18
A6: Operating Profit | B6: ='Data Sheet'!B55 -> 856.29 | C6: ='Data Sheet'!C55 -> 917.76 | D6: ='Data Sheet'!D55 -> 1037.94 | E6: ='Data Sheet'!E55 -> 996.85 | F6: ='Data Sheet'!F55 -> 1240.97 | G6: ='Data Sheet'!G55 -> 1340.36 | H6: ='Data Sheet'!H55 -> 1355.9 | I6: ='Data Sheet'!I55 -> 1321.17 | ... K6: ='Data Sheet'!K55 -> 2341.33
A7: Other Income | B7: ='Data Sheet'!B48 -> 22.83 | C7: ='Data Sheet'!C48 -> 40.4 | D7: ='Data Sheet'!D48 -> 29.37 | E7: ='Data Sheet'!E48 -> 29.25 | F7: ='Data Sheet'!F48 -> 67.78 | G7: ='Data Sheet'!G48 -> 42.29 | H7: ='Data Sheet'!H48 -> 53.71 | I7: ='Data Sheet'!I48 -> 56.95 | ... K7: ='Data Sheet'!K48 -> 90
A8: Depreciation | B8: ='Data Sheet'!B49 -> 234.66 | C8: ='Data Sheet'!C49 -> 247.85 | D8: ='Data Sheet'!D49 -> 257.2 | E8: ='Data Sheet'!E49 -> 457.1 | F8: ='Data Sheet'!F49 -> 247.71 | G8: ='Data Sheet'!G49 -> 256.92 | H8: ='Data Sheet'!H49 -> 271.45 | I8: ='Data Sheet'!I49 -> 393.18 | ... K8: ='Data Sheet'!K49 -> 316.77
A9: Interest | B9: ='Data Sheet'!B51 -> 85.67 | C9: ='Data Sheet'!C51 -> 80.64 | D9: ='Data Sheet'!D51 -> 74.01 | E9: ='Data Sheet'!E51 -> 71.29 | F9: ='Data Sheet'!F51 -> 68.01 | G9: ='Data Sheet'!G51 -> 70.87 | H9: ='Data Sheet'!H51 -> 66.89 | I9: ='Data Sheet'!I51 -> 89.1 | ... K9: ='Data Sheet'!K51 -> 107.59
A10: Profit before tax | B10: ='Data Sheet'!B52 -> 558.79 | C10: ='Data Sheet'!C52 -> 629.67 | D10: ='Data Sheet'!D52 -> 736.1 | E10: ='Data Sheet'!E52 -> 497.71 | F10: ='Data Sheet'!F52 -> 993.03 | G10: ='Data Sheet'!G52 -> 1054.86 | H10: ='Data Sheet'!H52 -> 1071.27 | I10: ='Data Sheet'!I52 -> 895.84 | ... K10: ='Data Sheet'!K52 -> 2006.97
A11: Tax | B11: ='Data Sheet'!B53 -> 105.46 | C11: ='Data Sheet'!C53 -> 134.35 | D11: ='Data Sheet'!D53 -> 117.4 | E11: ='Data Sheet'!E53 -> 129.49 | F11: ='Data Sheet'!F53 -> 187.49 | G11: ='Data Sheet'!G53 -> 195.38 | H11: ='Data Sheet'!H53 -> 212.41 | I11: ='Data Sheet'!I53 -> 113.46 | ... K11: ='Data Sheet'!K53 -> 522.14
A12: Net profit | B12: ='Data Sheet'!B54 -> 452.26 | C12: ='Data Sheet'!C54 -> 489.67 | D12: ='Data Sheet'!D54 -> 613.12 | E12: ='Data Sheet'!E54 -> 359.43 | F12: ='Data Sheet'!F54 -> 801.31 | G12: ='Data Sheet'!G54 -> 852.63 | H12: ='Data Sheet'!H54 -> 855.16 | I12: ='Data Sheet'!I54 -> 772.52 | ... K12: ='Data Sheet'!K54 -> 1477.92
A14: OPM | B14: =IF(B4>0,B6/B4,"") -> 0.17787273 | C14: =IF(C4>0,C6/C4,"") -> 0.18214728 | D14: =IF(D4>0,D6/D4,"") -> 0.19970331 | E14: =IF(E4>0,E6/E4,"") -> 0.20094582 | F14: =IF(F4>0,F6/F4,"") -> 0.22158873 | G14: =IF(G4>0,G6/G4,"") -> 0.2362813 | H14: =IF(H4>0,H6/H4,"") -> 0.23508463 | I14: =IF(I4>0,I6/I4,"") -> 0.23312859 | ... K14: =IF(K4>0,K6/K4,"") -> 0.33222088

Sheet Balance Sheet
A1: ='Profit & Loss'!A1 -> LUPIN LTD | E1: =UPDATE | J1: SCREENER.IN
A3: Narration | B3: ='Data Sheet'!B61 -> 42460 | C3: ='Data Sheet'!C61 -> 42825 | D3: ='Data Sheet'!D61 -> 43190 | E3: ='Data Sheet'!E61 -> 43555 | F3: ='Data Sheet'!F61 -> 43921 | G3: ='Data Sheet'!G61 -> 44286 | H3: ='Data Sheet'!H61 -> 44651 | I3: ='Data Sheet'!I61 -> 45016 | ... K3: ='Data Sheet'!K61 -> 45747
A4: Equity Share Capital | B4: ='Data Sheet'!B62 -> 90.12 | C4: ='Data Sheet'!C62 -> 90.32 | D4: ='Data Sheet'!D62 -> 90.42 | E4: ='Data Sheet'!E62 -> 90.5 | F4: ='Data Sheet'!F62 -> 90.6 | G4: ='Data Sheet'!G62 -> 90.74 | H4: ='Data Sheet'!H62 -> 90.9 | I4: ='Data Sheet'!I62 -> 91 | ... K4: ='Data Sheet'!K62 -> 91.32
A5: Reserves | B5: ='Data Sheet'!B63 -> 11073.25 | C5: ='Data Sheet'!C63 -> 13407.25 | D5: ='Data Sheet'!D63 -> 13486.64 | E5: ='Data Sheet'!E63 -> 13651.73 | F5: ='Data Sheet'!F63 -> 12446.1 | G5: ='Data Sheet'!G63 -> 13712.4 | H5: ='Data Sheet'!H63 -> 12062.37 | I5: ='Data Sheet'!I63 -> 12373.5 | ... K5: ='Data Sheet'!K63 -> 17112.18
A6: Borrowings | B6: ='Data Sheet'!B64 -> 7177.52 | C6: ='Data Sheet'!C64 -> 7966.09 | D6: ='Data Sheet'!D64 -> 7142.8 | E6: ='Data Sheet'!E64 -> 8496.07 | F6: ='Data Sheet'!F64 -> 6305.32 | G6: ='Data Sheet'!G64 -> 5129.08 | H6: ='Data Sheet'!H64 -> 4158.38 | I6: ='Data Sheet'!I64 -> 4541.52 | ... K6: ='Data Sheet'!K64 -> 5447.77
A7: Other Liabilities | B7: ='Data Sheet'!B65 -> 3957.29 | C7: ='Data Sheet'!C65 -> 4748.77 | D7: ='Data Sheet'!D65 -> 5299.99 | E7: ='Data Sheet'!E65 -> 5422.79 | F7: ='Data Sheet'!F65 -> 5967.52 | G7: ='Data Sheet'!G65 -> 4498.01 | H7: ='Data Sheet'!H65 -> 5339.84 | I7: ='Data Sheet'!I65 -> 5794.26 | ... K7: ='Data Sheet'!K65 -> 6327.2
A8: Total | B8: ='Data Sheet'!B66 -> 22298.18 | C8: ='Data Sheet'!C66 -> 26212.43 | D8: ='Data Sheet'!D66 -> 26019.85 | E8: ='Data Sheet'!E66 -> 27661.09 | F8: ='Data Sheet'!F66 -> 24809.54 | G8: ='Data Sheet'!G66 -> 23430.23 | H8: ='Data Sheet'!H66 -> 21651.49 | I8: ='Data Sheet'!I66 -> 22800.28 | ... K8: ='Data Sheet'!K66 -> 28978.47
A10: Net Block | B10: ='Data Sheet'!B67 -> 8716.96 | C10: ='Data Sheet'!C67 -> 11032.93 | D10: ='Data Sheet'!D67 -> 10361.99 | E10: ='Data Sheet'!E67 -> 11086.71 | F10: ='Data Sheet'!F67 -> 7938.11 | G10: ='Data Sheet'!G67 -> 7880.76 | H10: ='Data Sheet'!H67 -> 7381.62 | I10: ='Data Sheet'!I67 -> 8355.24 | ... K10: ='Data Sheet'!K67 -> 9719.35
A11: Capital Work in Progress | B11: ='Data Sheet'!B68 -> 2702.4 | C11: ='Data Sheet'!C68 -> 2133.06 | D11: ='Data Sheet'!D68 -> 2598.2 | E11: ='Data Sheet'!E68 -> 1639.71 | F11: ='Data Sheet'!F68 -> 939.62 | G11: ='Data Sheet'!G68 -> 1066.26 | H11: ='Data Sheet'!H68 -> 1146.28 | I11: ='Data Sheet'!I68 -> 1237.99 | ... K11: ='Data Sheet'!K68 -> 516.64
A12: Investments | B12: ='Data Sheet'!B69 -> 16.35 | C12: ='Data Sheet'!C69 -> 2136.13 | D12: ='Data Sheet'!D69 -> 261.57 | E12: ='Data Sheet'!E69 -> 2295.49 | F12: ='Data Sheet'!F69 -> 2374.32 | G12: ='Data Sheet'!G69 -> 2454.88 | H12: ='Data Sheet'!H69 -> 900 | I12: ='Data Sheet'!I69 -> 516.9 | ... K12: ='Data Sheet'!K69 -> 1146.38
A13: Other Assets | B13: ='Data Sheet'!B70 -> 10862.47 | C13: ='Data Sheet'!C70 -> 10910.31 | D13: ='Data Sheet'!D70 -> 12798.09 | E13: ='Data Sheet'!E70 -> 12639.18 | F13: ='Data Sheet'!F70 -> 13557.49 | G13: ='Data Sheet'!G70 -> 12028.33 | H13: ='Data Sheet'!H70 -> 12223.59 | I13: ='Data Sheet'!I70 -> 12690.15 | ... K13: ='Data Sheet'!K70 -> 17596.1
A14: Total | B14: ='Data Sheet'!B71 -> 22298.18 | C14: ='Data Sheet'!C71 -> 26212.43 | D14: ='Data Sheet'!D71 -> 26019.85 | E14: ='Data Sheet'!E71 -> 27661.09 | F14: ='Data Sheet'!F71 -> 24809.54 | G14: ='Data Sheet'!G71 -> 23430.23 | H14: ='Data Sheet'!H71 -> 21651.49 | I14: ='Data Sheet'!I71 -> 22800.28 | ... K14: ='Data Sheet'!K71 -> 28978.47
A16: Working Capital | B16: =B13-B7 -> 6905.18 | C16: =C13-C7 -> 6161.54 | D16: =D13-D7 -> 7498.1 | E16: =E13-E7 -> 7216.39 | F16: =F13-F7 -> 7589.97 | G16: =G13-G7 -> 7530.32 | H16: =H13-H7 -> 6883.75 | I16: =I13-I7 -> 6895.89 | ... K16: =K13-K7 -> 11268.9
A17: Debtors | B17: ='Data Sheet'!B72 -> 4548.76 | C17: ='Data Sheet'!C72 -> 4307.34 | D17: ='Data Sheet'!D72 -> 5192.21 | E17: ='Data Sheet'!E72 -> 5149.8 | F17: ='Data Sheet'!F72 -> 5445.93 | G17: ='Data Sheet'!G72 -> 4474.32 | H17: ='Data Sheet'!H72 -> 4261.94 | I17: ='Data Sheet'!I72 -> 4480.7 | ... K17: ='Data Sheet'!K72 -> 5497.1
A18: Inventory | B18: ='Data Sheet'!B73 -> 3273.65 | C18: ='Data Sheet'!C73 -> 3642.28 | D18: ='Data Sheet'!D73 -> 3662.49 | E18: ='Data Sheet'!E73 -> 3836.77 | F18: ='Data Sheet'!F73 -> 3456.87 | G18: ='Data Sheet'!G73 -> 4092.01 | H18: ='Data Sheet'!H73 -> 4630.73 | I18: ='Data Sheet'!I73 -> 4491.76 | ... K18: ='Data Sheet'!K73 -> 5476.35
A20: Debtor Days | B20: =IF('Profit & Loss'!B4>0,'Balance Sheet'!B17/('Profit & Loss'!B4/365),0) -> 116.46682 | C20: =IF('Profit & Loss'!C4>0,'Balance Sheet'!C17/('Profit & Loss'!C4/365),0) -> 90.524829 | D20: =IF('Profit & Loss'!D4>0,'Balance Sheet'!D17/('Profit & Loss'!D4/365),0) -> 119.97282 | E20: =IF('Profit & Loss'!E4>0,'Balance Sheet'!E17/('Profit & Loss'!E4/365),0) -> 128.17821 | F20: =IF('Profit & Loss'!F4>0,'Balance Sheet'!F17/('Profit & Loss'!F4/365),0) -> 129.28751 | G20: =IF('Profit & Loss'!G4>0,'Balance Sheet'!G17/('Profit & Loss'!G4/365),0) -> 107.70501 | H20: =IF('Profit & Loss'!H4>0,'Balance Sheet'!H17/('Profit & Loss'!H4/365),0) -> 94.822468 | I20: =IF('Profit & Loss'!I4>0,'Balance Sheet'!I17/('Profit & Loss'!I4/365),0) -> 98.274781 | ... K20: =IF('Profit & Loss'!K4>0,'Balance Sheet'!K17/('Profit & Loss'!K4/365),0) -> 88.358743
A21: Inventory Turnover | B21: =IF('Balance Sheet'!B18>0,'Profit & Loss'!B4/'Balance Sheet'!B18,0) -> 4.3546317 | C21: =IF('Balance Sheet'!C18>0,'Profit & Loss'!C4/'Balance Sheet'!C18,0) -> 4.7682715 | D21: =IF('Balance Sheet'!D18>0,'Profit & Loss'!D4/'Balance Sheet'!D18,0) -> 4.313063 | E21: =IF('Balance Sheet'!E18>0,'Profit & Loss'!E4/'Balance Sheet'!E18,0) -> 3.8221108 | F21: =IF('Balance Sheet'!F18>0,'Profit & Loss'!F4/'Balance Sheet'!F18,0) -> 4.4475957 | G21: =IF('Balance Sheet'!G18>0,'Profit & Loss'!G4/'Balance Sheet'!G18,0) -> 3.7055041 | H21: =IF('Balance Sheet'!H18>0,'Profit & Loss'!H4/'Balance Sheet'!H18,0) -> 3.5427416 | I21: =IF('Balance Sheet'!I18>0,'Profit & Loss'!I4/'Balance Sheet'!I18,0) -> 3.7049308 | ... K21: =IF('Balance Sheet'!K18>0,'Profit & Loss'!K4/'Balance Sheet'!K18,0) -> 4.1465392
A23: Return on Equity | B23: =IF(SUM('Balance Sheet'!B4:B5)>0,'Profit & Loss'!B12/SUM('Balance Sheet'!B4:B5),"") -> 0.20251412 | C23: =IF(SUM('Balance Sheet'!C4:C5)>0,'Profit & Loss'!C12/SUM('Balance Sheet'!C4:C5),"") -> 0.18947559 | D23: =IF(SUM('Balance Sheet'!D4:D5)>0,'Profit & Loss'!D12/SUM('Balance Sheet'!D4:D5),"") -> 0.018506216 | E23: =IF(SUM('Balance Sheet'!E4:E5)>0,'Profit & Loss'!E12/SUM('Balance Sheet'!E4:E5),"") -> 0.044137669 | F23: =IF(SUM('Balance Sheet'!F4:F5)>0,'Profit & Loss'!F12/SUM('Balance Sheet'!F4:F5),"") -> -0.021488111 | G23: =IF(SUM('Balance Sheet'!G4:G5)>0,'Profit & Loss'!G12/SUM('Balance Sheet'!G4:G5),"") -> 0.088134294 | H23: =IF(SUM('Balance Sheet'!H4:H5)>0,'Profit & Loss'!H12/SUM('Balance Sheet'!H4:H5),"") -> -0.12573077 | I23: =IF(SUM('Balance Sheet'!I4:I5)>0,'Profit & Loss'!I12/SUM('Balance Sheet'!I4:I5),"") -> 0.034504392 | ... K23: =IF(SUM('Balance Sheet'!K4:K5)>0,'Profit & Loss'!K12/SUM('Balance Sheet'!K4:K5),"") -> 0.19075304
A24: Return on Capital Emp | C24: =IF((B4+B5+B6+C4+C5+C6)>0,('Profit & Loss'!C10+'Profit & Loss'!C9)*2/(B4+B5+B6+C4+C5+C6),"") -> 0.18569083 | D24: =IF((C4+C5+C6+D4+D5+D6)>0,('Profit & Loss'!D10+'Profit & Loss'!D9)*2/(C4+C5+C6+D4+D5+D6),"") -> 0.035613908 | E24: =IF((D4+D5+D6+E4+E5+E6)>0,('Profit & Loss'!E10+'Profit & Loss'!E9)*2/(D4+D5+D6+E4+E5+E6),"") -> 0.084077623 | F24: =IF((E4+E5+E6+F4+F5+F6)>0,('Profit & Loss'!F10+'Profit & Loss'!F9)*2/(E4+E5+E6+F4+F5+F6),"") -> 0.060871483 | G24: =IF((F4+F5+F6+G4+G5+G6)>0,('Profit & Loss'!G10+'Profit & Loss'!G9)*2/(F4+F5+F6+G4+G5+G6),"") -> 0.096207892 | H24: =IF((G4+G5+G6+H4+H5+H6)>0,('Profit & Loss'!H10+'Profit & Loss'!H9)*2/(G4+G5+G6+H4+H5+H6),"") -> -0.069767594 | I24: =IF((H4+H5+H6+I4+I5+I6)>0,('Profit & Loss'!I10+'Profit & Loss'!I9)*2/(H4+H5+H6+I4+I5+I6),"") -> 0.059475347 | J24: =IF((I4+I5+I6+J4+J5+J6)>0,('Profit & Loss'!J10+'Profit & Loss'!J9)*2/(I4+I5+I6+J4+J5+J6),"") -> 0.15979155 | K24: =IF((J4+J5+J6+K4+K5+K6)>0,('Profit & Loss'!K10+'Profit & Loss'!K9)*2/(J4+J5+J6+K4+K5+K6),"") -> 0.21623231

Sheet Cash Flow
A1: ='Balance Sheet'!A1 -> LUPIN LTD | E1: =UPDATE | J1: SCREENER.IN
A3: Narration | B3: ='Data Sheet'!B86 -> 42460 | C3: ='Data Sheet'!C86 -> 42825 | D3: ='Data Sheet'!D86 -> 43190 | E3: ='Data Sheet'!E86 -> 43555 | F3: ='Data Sheet'!F86 -> 43921 | G3: ='Data Sheet'!G86 -> 44286 | H3: ='Data Sheet'!H86 -> 44651 | I3: ='Data Sheet'!I86 -> 45016 | ... K3: ='Data Sheet'!K86 -> 45747
A4: Cash from Operating Activity | B4: ='Data Sheet'!B87 -> -382.39 | C4: ='Data Sheet'!C87 -> 4113.51 | D4: ='Data Sheet'!D87 -> 1751.19 | E4: ='Data Sheet'!E87 -> 1665.97 | F4: ='Data Sheet'!F87 -> 1468.84 | G4: ='Data Sheet'!G87 -> 1821.76 | H4: ='Data Sheet'!H87 -> 367.31 | I4: ='Data Sheet'!I87 -> 1897.24 | ... K4: ='Data Sheet'!K87 -> 2999.94
A5: Cash from Investing Activity | B5: ='Data Sheet'!B88 -> -6768.83 | C5: ='Data Sheet'!C88 -> -2527.44 | D5: ='Data Sheet'!D88 -> 469.87 | E5: ='Data Sheet'!E88 -> -3282.47 | F5: ='Data Sheet'!F88 -> 1106.99 | G5: ='Data Sheet'!G88 -> -1239.58 | H5: ='Data Sheet'!H88 -> 1292.23 | I5: ='Data Sheet'!I88 -> -1286.77 | ... K5: ='Data Sheet'!K88 -> -4171.89
A6: Cash from Financing Activity | B6: ='Data Sheet'!B89 -> 5836.38 | C6: ='Data Sheet'!C89 -> 433.18 | D6: ='Data Sheet'!D89 -> -1492.09 | E6: ='Data Sheet'!E89 -> 744.13 | F6: ='Data Sheet'!F89 -> -890.58 | G6: ='Data Sheet'!G89 -> -1885.27 | H6: ='Data Sheet'!H89 -> -1572.32 | I6: ='Data Sheet'!I89 -> -337.25 | ... K6: ='Data Sheet'!K89 -> 1731.88
A7: Net Cash Flow | B7: ='Data Sheet'!B90 -> -1314.84 | C7: ='Data Sheet'!C90 -> 2019.25 | D7: ='Data Sheet'!D90 -> 728.97 | E7: ='Data Sheet'!E90 -> -872.37 | F7: ='Data Sheet'!F90 -> 1685.25 | G7: ='Data Sheet'!G90 -> -1303.09 | H7: ='Data Sheet'!H90 -> 87.22 | I7: ='Data Sheet'!I90 -> 273.22 | ... K7: ='Data Sheet'!K90 -> 559.93

Sheet Customization
A1: How to use it?
A3: You can customize this workbook as you want.
B4: You can add custom formating, add conditional formating, add your own formulas… do ANYTHING.
B5: Please don't edit the "Data Sheet" only.
A7: After customization, you can upload this back on Screener.
B8: Upload on: | C8: https://www.screener.in/excel/
A10: Download your customized workbooks now onwards.
B11: Now whenever you will "Export to excel" from Screener, it will export your customized file.
A14: TESTING:
B15: This is a testing feature currently.
B16: You can report any formula errors on the worksheet at: support@screener.in
